<?xml version='1.0' encoding='utf-8'?>
<robot name="jaka">
  <mujoco>
    <compiler meshdir="./meshes" balanceinertia="true" discardvisual="false" />
  </mujoco>


  <link name="LINK_BASE">
    <visual>
      <origin xyz="0 0 0" rpy="0 0 0" />
      <geometry>
        <mesh filename="package://robotics/drivers/manipulators/jaka/description/meshes/LINK_BASE.STL" />
      </geometry>
      <material name="">
        <color rgba="0.898039215686275 0.917647058823529 0.929411764705882 1" />
      </material>
    </visual>
    <collision>
      <origin xyz="0 0 0" rpy="0 0 0" />
      <geometry>
        <mesh filename="package://robotics/drivers/manipulators/jaka/description/meshes/LINK_BASE.STL" />
      </geometry>
    </collision>
  </link>
  <link name="LINK_1">
    <inertial>
      <origin xyz="-2.45882405230935E-06 -3.29465041054577E-07 0.164278748238539" rpy="0 0 0" />
      <mass value="1.4911451291693" />
      <inertia ixx="0.00305995014022009" ixy="1.23264704380858E-07" ixz="4.84189868924744E-08" iyy="0.00378498860937097" iyz="-4.00260806599368E-08" izz="0.00212611420638739" />
    </inertial>
    <visual>
      <origin xyz="0 0 0" rpy="0 0 0" />
      <geometry>
        <mesh filename="package://robotics/drivers/manipulators/jaka/description/meshes/LINK_1.STL" />
      </geometry>
      <material name="">
        <color rgba="0.898039215686275 0.917647058823529 0.929411764705882 1" />
      </material>
    </visual>
    <collision>
      <origin xyz="0 0 0" rpy="0 0 0" />
      <geometry>
        <mesh filename="package://robotics/drivers/manipulators/jaka/description/meshes/LINK_1.STL" />
      </geometry>
    </collision>
  </link>
  <joint name="J_1" type="revolute">
    <origin xyz="0 -0.016 0.22" rpy="1.5708 0 0" />
    <parent link="LINK_BASE" />
    <child link="LINK_1" />
    <axis xyz="0 0 1" />
    <limit lower="-6.2832" upper="6.2832" effort="0" velocity="0" />
  </joint>
  <link name="LINK_2">
    <inertial>
      <origin xyz="-1.73912983855717E-05 -0.0453022891900061 0.000758985811081109" rpy="0 0 0" />
      <mass value="2.70307080056574" />
      <inertia ixx="0.00985116104091467" ixy="-3.38766701448687E-06" ixz="-5.61641762497661E-10" iyy="0.00588775168674882" iyz="-9.30811796886939E-05" izz="0.00748059216406987" />
    </inertial>
    <visual>
      <origin xyz="0 0 0" rpy="0 0 0" />
      <geometry>
        <mesh filename="package://robotics/drivers/manipulators/jaka/description/meshes/LINK_2.STL" />
      </geometry>
      <material name="">
        <color rgba="0.898039215686275 0.917647058823529 0.929411764705882 1" />
      </material>
    </visual>
    <collision>
      <origin xyz="0 0 0" rpy="0 0 0" />
      <geometry>
        <mesh filename="package://robotics/drivers/manipulators/jaka/description/meshes/LINK_2.STL" />
      </geometry>
    </collision>
  </link>
  <joint name="J_2" type="revolute">
    <origin xyz="0 0 0.2075" rpy="-1.5708 0 -3.1416" />
    <parent link="LINK_1" />
    <child link="LINK_2" />
    <axis xyz="0 0 1" />
    <limit lower="-1.8325" upper="1.8325" effort="0" velocity="0" />
  </joint>
  <link name="LINK_3">
    <inertial>
      <origin xyz="0.00781892927895886 0.000443169694662265 0.236718911091754" rpy="0 0 0" />
      <mass value="3.54660277070567" />
      <inertia ixx="0.0185269491158126" ixy="1.22803072043E-06" ixz="-0.000120248224529112" iyy="0.0186931698742112" iyz="1.68848256376357E-05" izz="0.00375206007609043" />
    </inertial>
    <visual>
      <origin xyz="0 0 0" rpy="0 0 0" />
      <geometry>
        <mesh filename="package://robotics/drivers/manipulators/jaka/description/meshes/LINK_3.STL" />
      </geometry>
      <material name="">
        <color rgba="0.898039215686275 0.917647058823529 0.929411764705882 1" />
      </material>
    </visual>
    <collision>
      <origin xyz="0 0 0" rpy="0 0 0" />
      <geometry>
        <mesh filename="package://robotics/drivers/manipulators/jaka/description/meshes/LINK_3.STL" />
      </geometry>
    </collision>
  </link>
  <joint name="J_3" type="revolute">
    <origin xyz="0 0 0" rpy="1.5708 0 0" />
    <parent link="LINK_2" />
    <child link="LINK_3" />
    <axis xyz="0 0 1" />
    <limit lower="-6.2832" upper="6.2832" effort="0" velocity="0" />
  </joint>
  <link name="LINK_4">
    <inertial>
      <origin xyz="0.00464860390905572 -0.0316068170756088 0.000433524702296156" rpy="0 0 0" />
      <mass value="1.4740751978085" />
      <inertia ixx="0.00379436123700012" ixy="0.000160580388960059" ixz="2.463775003913E-07" iyy="0.00225645609791798" iyz="7.77499812854555E-06" izz="0.00281220282723288" />
    </inertial>
    <visual>
      <origin xyz="0 0 0" rpy="0 0 0" />
      <geometry>
        <mesh filename="package://robotics/drivers/manipulators/jaka/description/meshes/LINK_4.STL" />
      </geometry>
      <material name="">
        <color rgba="0.898039215686275 0.917647058823529 0.929411764705882 1" />
      </material>
    </visual>
    <collision>
      <origin xyz="0 0 0" rpy="0 0 0" />
      <geometry>
        <mesh filename="package://robotics/drivers/manipulators/jaka/description/meshes/LINK_4.STL" />
      </geometry>
    </collision>
  </link>
  <joint name="J_4" type="revolute">
    <origin xyz="0.00040027 0 0.33028" rpy="-1.5708 0 0" />
    <parent link="LINK_3" />
    <child link="LINK_4" />
    <axis xyz="0 0 1" />
    <limit lower="-2.5307" upper="0.5235" effort="0" velocity="0" />
  </joint>
  <link name="LINK_5">
    <inertial>
      <origin xyz="-2.41117716229255E-06 0.00407933088083326 0.183521132964771" rpy="0 0 0" />
      <mass value="2.28121145937996" />
      <inertia ixx="0.00549376131725597" ixy="1.63293925677592E-07" ixz="1.60661986212534E-07" iyy="0.00558037684698882" iyz="-0.000384345841898039" izz="0.00195950697428382" />
    </inertial>
    <visual>
      <origin xyz="0 0 0" rpy="0 0 0" />
      <geometry>
        <mesh filename="package://robotics/drivers/manipulators/jaka/description/meshes/LINK_5.STL" />
      </geometry>
      <material name="">
        <color rgba="0.898039215686275 0.917647058823529 0.929411764705882 1" />
      </material>
    </visual>
    <collision>
      <origin xyz="0 0 0" rpy="0 0 0" />
      <geometry>
        <mesh filename="package://robotics/drivers/manipulators/jaka/description/meshes/LINK_5.STL" />
      </geometry>
    </collision>
  </link>
  <joint name="J_5" type="revolute">
    <origin xyz="0 0 0" rpy="1.5708 0 0" />
    <parent link="LINK_4" />
    <child link="LINK_5" />
    <axis xyz="0 0 1" />
    <limit lower="-6.2832" upper="6.2832" effort="0" velocity="0" />
  </joint>
  <link name="LINK_6">
    <inertial>
      <origin xyz="-3.20485854715669E-07 -0.0871588885243756 0.0055418304220777" rpy="0 0 0" />
      <mass value="1.76792309993444" />
      <inertia ixx="0.00447235828112751" ixy="4.71470154551187E-08" ixz="1.19024726211431E-08" iyy="0.00158251986788253" iyz="-0.000773038350906083" izz="0.00428293497285685" />
    </inertial>
    <visual>
      <origin xyz="0 0 0" rpy="0 0 0" />
      <geometry>
        <mesh filename="package://robotics/drivers/manipulators/jaka/description/meshes/LINK_6.STL" />
      </geometry>
      <material name="">
        <color rgba="0.898039215686275 0.917647058823529 0.929411764705882 1" />
      </material>
    </visual>
    <collision>
      <origin xyz="0 0 0" rpy="0 0 0" />
      <geometry>
        <mesh filename="package://robotics/drivers/manipulators/jaka/description/meshes/LINK_6.STL" />
      </geometry>
    </collision>
  </link>
  <joint name="J_6" type="revolute">
    <origin xyz="0 0 0.23494" rpy="-1.5708 0 -3.1416" />
    <parent link="LINK_5" />
    <child link="LINK_6" />
    <axis xyz="0 0 1" />
    <limit lower="-1.8325" upper="1.8325" effort="0" velocity="0" />
  </joint>
  <link name="LINK_7">
    <inertial>
      <origin xyz="2.69436515709653E-07 -3.01174900691481E-05 0.176617274894147" rpy="0 0 0" />
      <mass value="0.634983447813081" />
      <inertia ixx="0.000369700889597725" ixy="7.98244027199847E-20" ixz="3.00795932024965E-20" iyy="0.000370207332440143" iyz="4.29842702140539E-07" izz="0.000512144747874418" />
    </inertial>
    <visual>
      <origin xyz="0 0 0" rpy="0 0 0" />
      <geometry>
        <mesh filename="package://robotics/drivers/manipulators/jaka/description/meshes/LINK_7.STL" />
      </geometry>
      <material name="">
        <color rgba="1 1 1 1" />
      </material>
    </visual>
    <collision>
      <origin xyz="0 0 0" rpy="0 0 0" />
      <geometry>
        <mesh filename="package://robotics/drivers/manipulators/jaka/description/meshes/LINK_7.STL" />
      </geometry>
    </collision>
  </link>
  <joint name="J_7" type="revolute">
    <origin xyz="0 0 0" rpy="1.5708 0 0" />
    <parent link="LINK_6" />
    <child link="LINK_7" />
    <axis xyz="0 0 1" />
    <limit lower="-6.2832" upper="6.2832" effort="0" velocity="0" />
  </joint>
</robot>
